Workbook

Sheet Dashboard
A1: Budget-Dashboard FY26 → FY27
A2: Interaktive Auswertung: die beiden Auswahlfelder unten steuern Kennzahlen, Tabellen und Diagramme.
A3: Hinweis: Cost Center DE2060502 (IPS Management Office NCE) ist auf Anforderung vollständig aus dieser Auswertung ausgeschlossen – mit beiden Jahreswerten.
A4: Filter
A5: Cost Center: | C5: Alle
A7: Thema: | C7: Alle
C8: Gelbe Felder = Auswahl (Dropdown).
A10: Kennzahlen | B10: Budget FY26 | C10: Budget FY27 | D10: Delta (EUR) | E10: Delta % | F10: Positionen | G10: davon neu | H10: davon entfallen
B11: =SUMIFS(Positionen!$K$3:$K$74,Positionen!$A$3:$A$74,Berechnung!$O$4,Positionen!$E$3:$E$74,Berechnung!$O$5) -> 16164300 | C11: =SUMIFS(Positionen!$L$3:$L$74,Positionen!$A$3:$A$74,Berechnung!$O$4,Positionen!$E$3:$E$74,Berechnung!$O$5) -> 18380095 | D11: =C11-B11 -> 2215795 | E11: =IF(B11=0,"",D11/B11) -> 0.13707955 | F11: =COUNTIFS(Positionen!$A$3:$A$74,Berechnung!$O$4,Positionen!$E$3:$E$74,Berechnung!$O$5) -> 72 | G11: =COUNTIFS(Positionen!$A$3:$A$74,Berechnung!$O$4,Positionen!$E$3:$E$74,Berechnung!$O$5,Positionen!$O$3:$O$74,"neu") -> 13 | H11: =COUNTIFS(Positionen!$A$3:$A$74,Berechnung!$O$4,Positionen!$E$3:$E$74,Berechnung!$O$5,Positionen!$O$3:$O$74,"entfallen") -> 5
A56: Top 12 Veränderungen (gemäß Filter)
A57: Position | B57: Cost Center | C57: Thema | D57: FY26 | E57: FY27 | F57: Delta (EUR) | G57: Status
A58: =IF(Berechnung!A119="","",Berechnung!A119) -> ServiceNow SEPM Projekt Gestehung 2027 (D-020932) | B58: =IF(Berechnung!E119="","",Berechnung!E119) -> DE2060204 | C58: =IF(Berechnung!F119="","",Berechnung!F119) -> ITSM & ServiceNow | D58: =IF(Berechnung!C119="","",Berechnung!C119) -> 0 | E58: =IF(Berechnung!D119="","",Berechnung!D119) -> 800000 | F58: =IF(Berechnung!B119="","",Berechnung!B119) -> 800000 | G58: =IF(Berechnung!G119="","",Berechnung!G119) -> neu
A59: =IF(Berechnung!A120="","",Berechnung!A120) -> Unified Communication Managed Service | B59: =IF(Berechnung!E120="","",Berechnung!E120) -> DE206210 | C59: =IF(Berechnung!F120="","",Berechnung!F120) -> Unified Communications & Telefonie | D59: =IF(Berechnung!C120="","",Berechnung!C120) -> 0 | E59: =IF(Berechnung!D120="","",Berechnung!D120) -> 490000 | F59: =IF(Berechnung!B120="","",Berechnung!B120) -> 490000 | G59: =IF(Berechnung!G120="","",Berechnung!G120) -> neu
A60: =IF(Berechnung!A121="","",Berechnung!A121) -> ServiceNow Modul IT Operation Monitoring ITOM (D-020936) | B60: =IF(Berechnung!E121="","",Berechnung!E121) -> DE2060204 | C60: =IF(Berechnung!F121="","",Berechnung!F121) -> ITSM & ServiceNow | D60: =IF(Berechnung!C121="","",Berechnung!C121) -> 0 | E60: =IF(Berechnung!D121="","",Berechnung!D121) -> 400000 | F60: =IF(Berechnung!B121="","",Berechnung!B121) -> 400000 | G60: =IF(Berechnung!G121="","",Berechnung!G121) -> neu
A61: =IF(Berechnung!A122="","",Berechnung!A122) -> ServiceNow Enterpise Contract | B61: =IF(Berechnung!E122="","",Berechnung!E122) -> DE2060204 | C61: =IF(Berechnung!F122="","",Berechnung!F122) -> ITSM & ServiceNow | D61: =IF(Berechnung!C122="","",Berechnung!C122) -> 725000 | E61: =IF(Berechnung!D122="","",Berechnung!D122) -> 1100000 | F61: =IF(Berechnung!B122="","",Berechnung!B122) -> 375000 | G61: =IF(Berechnung!G122="","",Berechnung!G122) -> erhöht
A62: =IF(Berechnung!A123="","",Berechnung!A123) -> M365 Copilot und Copilot Studio | B62: =IF(Berechnung!E123="","",Berechnung!E123) -> DE206210 | C62: =IF(Berechnung!F123="","",Berechnung!F123) -> KI & Copilot | D62: =IF(Berechnung!C123="","",Berechnung!C123) -> 450000 | E62: =IF(Berechnung!D123="","",Berechnung!D123) -> 225000 | F62: =IF(Berechnung!B123="","",Berechnung!B123) -> -225000 | G62: =IF(Berechnung!G123="","",Berechnung!G123) -> reduziert
A63: =IF(Berechnung!A124="","",Berechnung!A124) -> ServiceNow Plattform Maintenance | B63: =IF(Berechnung!E124="","",Berechnung!E124) -> DE2060204 | C63: =IF(Berechnung!F124="","",Berechnung!F124) -> ITSM & ServiceNow | D63: =IF(Berechnung!C124="","",Berechnung!C124) -> 0 | E63: =IF(Berechnung!D124="","",Berechnung!D124) -> 140000 | F63: =IF(Berechnung!B124="","",Berechnung!B124) -> 140000 | G63: =IF(Berechnung!G124="","",Berechnung!G124) -> neu
A64: =IF(Berechnung!A125="","",Berechnung!A125) -> ServiceNow Plattform Managed Service Operation | B64: =IF(Berechnung!E125="","",Berechnung!E125) -> DE2060204 | C64: =IF(Berechnung!F125="","",Berechnung!F125) -> ITSM & ServiceNow | D64: =IF(Berechnung!C125="","",Berechnung!C125) -> 0 | E64: =IF(Berechnung!D125="","",Berechnung!D125) -> 120000 | F64: =IF(Berechnung!B125="","",Berechnung!B125) -> 120000 | G64: =IF(Berechnung!G125="","",Berechnung!G125) -> neu
A65: =IF(Berechnung!A126="","",Berechnung!A126) -> L-EDV Client | B65: =IF(Berechnung!E126="","",Berechnung!E126) -> DE2060204 | C65: =IF(Berechnung!F126="","",Berechnung!F126) -> Client & Endgeräte (L-EDV) | D65: =IF(Berechnung!C126="","",Berechnung!C126) -> 2900000 | E65: =IF(Berechnung!D126="","",Berechnung!D126) -> 3000000 | F65: =IF(Berechnung!B126="","",Berechnung!B126) -> 100000 | G65: =IF(Berechnung!G126="","",Berechnung!G126) -> erhöht
A66: =IF(Berechnung!A127="","",Berechnung!A127) -> ServiceNow SPM - Strategic Portfolio Management (D-020932) | B66: =IF(Berechnung!E127="","",Berechnung!E127) -> DE2060204 | C66: =IF(Berechnung!F127="","",Berechnung!F127) -> ITSM & ServiceNow | D66: =IF(Berechnung!C127="","",Berechnung!C127) -> 110000 | E66: =IF(Berechnung!D127="","",Berechnung!D127) -> 200000 | F66: =IF(Berechnung!B127="","",Berechnung!B127) -> 90000 | G66: =IF(Berechnung!G127="","",Berechnung!G127) -> erhöht
A67: =IF(Berechnung!A128="","",Berechnung!A128) -> ServiceNow Modul Release Management (SAP) | B67: =IF(Berechnung!E128="","",Berechnung!E128) -> DE2060204 | C67: =IF(Berechnung!F128="","",Berechnung!F128) -> ITSM & ServiceNow | D67: =IF(Berechnung!C128="","",Berechnung!C128) -> 85000 | E67: =IF(Berechnung!D128="","",Berechnung!D128) -> 0 | F67: =IF(Berechnung!B128="","",Berechnung!B128) -> -85000 | G67: =IF(Berechnung!G128="","",Berechnung!G128) -> entfallen
A68: =IF(Berechnung!A129="","",Berechnung!A129) -> ITSM Development | B68: =IF(Berechnung!E129="","",Berechnung!E129) -> DE2060204 | C68: =IF(Berechnung!F129="","",Berechnung!F129) -> ITSM & ServiceNow | D68: =IF(Berechnung!C129="","",Berechnung!C129) -> 85000 | E68: =IF(Berechnung!D129="","",Berechnung!D129) -> 0 | F68: =IF(Berechnung!B129="","",Berechnung!B129) -> -85000 | G68: =IF(Berechnung!G129="","",Berechnung!G129) -> entfallen
A69: =IF(Berechnung!A130="","",Berechnung!A130) -> Webex FlexPlan - Suite | B69: =IF(Berechnung!E130="","",Berechnung!E130) -> DE206210 | C69: =IF(Berechnung!F130="","",Berechnung!F130) -> Unified Communications & Telefonie | D69: =IF(Berechnung!C130="","",Berechnung!C130) -> 0 | E69: =IF(Berechnung!D130="","",Berechnung!D130) -> 75000 | F69: =IF(Berechnung!B130="","",Berechnung!B130) -> 75000 | G69: =IF(Berechnung!G130="","",Berechnung!G130) -> neu
A71: Kreuzfilter-Logik: Das Themen-Diagramm folgt dem Cost-Center-Filter, das Cost-Center-Diagramm dem Themen-Filter; Kostenarten, Kennzahlen und Top-Liste folgen beiden Filtern. Grundlage ist stets die bereinigte Cost-Center-Sicht.

Sheet Cost Center
A1: Budgetentwicklung je Cost Center: FY26 → FY27
A2: Quelle: sFinx-Export vom 25.08.2026 · Werte in EUR · alle Zellen sind Formeln auf Blatt "Positionen"
A3: Hinweis: Cost Center DE2060502 (IPS Management Office NCE) ist auf Anforderung vollständig aus dieser Auswertung ausgeschlossen – mit beiden Jahreswerten.
A4: A) Organisatorische Überführung FY26 → FY27
A5: Vorgabe des Fachbereichs. Diese Zuordnung steuert die bereinigte Sicht (Block C) und die Spalte "Bemerkung" auf dem Blatt "Positionen".
A6: Cost Center FY26 | B6: Bezeichnung FY26 | C6: Cost Center FY27 | D6: Bezeichnung FY27 | E6: Art der Überführung
A7: DE2060202 | B7: DE2060202 - ITSM+ServiceNow NCE | C7: DE2060204 | D7: DE2060204 - Support & Operations NCE | E7: in DE2060204 integriert
A8: DE2060203 | B8: DE2060203 - Digital Collabo. NCE | C8: DE206210 | D8: DE206210 - Modern Workplace & Experience | E8: nach DE206210 überführt
A9: DE2060204 | B9: DE2060204 - Serv. Desk+Sup.NCE | C9: DE2060204 | D9: DE2060204 - Support & Operations NCE | E9: unverändert fortgeführt
A11: B) Ist-Sicht – Budget wie im Export gebucht
A12: FY26-Werte am FY26-Cost-Center, FY27-Werte am FY27-Cost-Center. Die Überführung aus Block A schlägt hier voll durch: abgebende Cost Center weisen FY27 keinen Wert mehr aus.
A13: Cost Center Code | B13: Bezeichnung FY26 | C13: Bezeichnung FY27 | D13: Budget FY26 | E13: Budget FY27 | F13: Delta (EUR) | G13: Delta % | H13: Anteil FY27
A14: DE2060202 | B14: DE2060202 - ITSM+ServiceNow NCE | C14: – (in FY27 entfallen) | D14: =SUMIFS(Positionen!$K$3:$K$74,Positionen!$C$3:$C$74,$A14) -> 1055000 | E14: =SUMIFS(Positionen!$L$3:$L$74,Positionen!$D$3:$D$74,$A14) -> 0 | F14: =E14-D14 -> -1055000 | G14: =IF(D14=0,"",F14/D14) -> -1 | H14: =IF($E$18=0,"",E14/$E$18) -> 0
A15: DE2060203 | B15: DE2060203 - Digital Collabo. NCE | C15: – (in FY27 entfallen) | D15: =SUMIFS(Positionen!$K$3:$K$74,Positionen!$C$3:$C$74,$A15) -> 10498600 | E15: =SUMIFS(Positionen!$L$3:$L$74,Positionen!$D$3:$D$74,$A15) -> 0 | F15: =E15-D15 -> -10498600 | G15: =IF(D15=0,"",F15/D15) -> -1 | H15: =IF($E$18=0,"",E15/$E$18) -> 0
A16: DE2060204 | B16: DE2060204 - Serv. Desk+Sup.NCE | C16: DE2060204 - Support & Operations NCE | D16: =SUMIFS(Positionen!$K$3:$K$74,Positionen!$C$3:$C$74,$A16) -> 4610700 | E16: =SUMIFS(Positionen!$L$3:$L$74,Positionen!$D$3:$D$74,$A16) -> 7576000 | F16: =E16-D16 -> 2965300 | G16: =IF(D16=0,"",F16/D16) -> 0.64313445 | H16: =IF($E$18=0,"",E16/$E$18) -> 0.41218503
A17: DE206210 | B17: – (in FY26 nicht vorhanden) | C17: DE206210 - Modern Workplace & Experience | D17: =SUMIFS(Positionen!$K$3:$K$74,Positionen!$C$3:$C$74,$A17) -> 0 | E17: =SUMIFS(Positionen!$L$3:$L$74,Positionen!$D$3:$D$74,$A17) -> 10804095 | F17: =E17-D17 -> 10804095 | G17: =IF(D17=0,"",F17/D17) | H17: =IF($E$18=0,"",E17/$E$18) -> 0.58781497
A18: Gesamt | D18: =SUM(D14:D17) -> 16164300 | E18: =SUM(E14:E17) -> 18380095 | F18: =SUM(F14:F17) -> 2215795 | G18: =IF(D18=0,"",F18/D18) -> 0.13707955 | H18: =IF(E18=0,"",E18/E18) -> 1
A21: C) Vergleichbare Sicht – organisatorisch bereinigt
A22: FY26- und FY27-Werte einer Position werden gemeinsam dem FY27-Cost-Center aus Block A zugeordnet (Spalte "Cost Center (Sicht)"). So wird die reine Budgetentwicklung ohne Reorganisationseffekt sichtbar.
A23: Cost Center Code (FY27) | B23: Vorgänger FY26 | C23: Bezeichnung FY27 | D23: Budget FY26 | E23: Budget FY27 | F23: Delta (EUR) | G23: Delta % | H23: Anteil FY27
A24: DE2060204 | B24: DE2060202 (ITSM+ServiceNow NCE) + DE2060204 (Serv. Desk+Sup.NCE) | C24: DE2060204 - Support & Operations NCE | D24: =SUMIFS(Positionen!$K$3:$K$74,Positionen!$A$3:$A$74,$A24) -> 5665700 | E24: =SUMIFS(Positionen!$L$3:$L$74,Positionen!$A$3:$A$74,$A24) -> 7576000 | F24: =E24-D24 -> 1910300 | G24: =IF(D24=0,"",F24/D24) -> 0.33716928 | H24: =IF($E$26=0,"",E24/$E$26) -> 0.41218503
A25: DE206210 | B25: DE2060203 (Digital Collabo. NCE) | C25: DE206210 - Modern Workplace & Experience | D25: =SUMIFS(Positionen!$K$3:$K$74,Positionen!$A$3:$A$74,$A25) -> 10498600 | E25: =SUMIFS(Positionen!$L$3:$L$74,Positionen!$A$3:$A$74,$A25) -> 10804095 | F25: =E25-D25 -> 305495 | G25: =IF(D25=0,"",F25/D25) -> 0.029098642 | H25: =IF($E$26=0,"",E25/$E$26) -> 0.58781497
A26: Gesamt | D26: =SUM(D24:D25) -> 16164300 | E26: =SUM(E24:E25) -> 18380095 | F26: =SUM(F24:F25) -> 2215795 | G26: =IF(D26=0,"",F26/D26) -> 0.13707955 | H26: =IF(E26=0,"",E26/E26) -> 1

Sheet Themen
A1: Budgetentwicklung je Thema: FY26 → FY27
A2: Themen sind fachliche Bündel der Einzelpositionen (Zuordnungsregeln siehe Blatt "Legende")
A3: Hinweis: Cost Center DE2060502 (IPS Management Office NCE) ist auf Anforderung vollständig aus dieser Auswertung ausgeschlossen – mit beiden Jahreswerten.
A4: A) Entwicklung je Thema (alle Cost Center)
A5: Thema | B5: Budget FY26 | C5: Budget FY27 | D5: Delta (EUR) | E5: Delta % | F5: Anteil FY27 | G5: Positionen | H5: davon neu | I5: davon entfallen
A6: Client & Endgeräte (L-EDV) | B6: =SUMIFS(Positionen!$K$3:$K$74,Positionen!$E$3:$E$74,$A6) -> 3953000 | C6: =SUMIFS(Positionen!$L$3:$L$74,Positionen!$E$3:$E$74,$A6) -> 4105500 | D6: =C6-B6 -> 152500 | E6: =IF(B6=0,"",D6/B6) -> 0.038578295 | F6: =IF($C$16=0,"",C6/$C$16) -> 0.22336664 | G6: =COUNTIFS(Positionen!$E$3:$E$74,$A6) -> 8 | H6: =COUNTIFS(Positionen!$E$3:$E$74,$A6,Positionen!$O$3:$O$74,"neu") -> 0 | I6: =COUNTIFS(Positionen!$E$3:$E$74,$A6,Positionen!$O$3:$O$74,"entfallen") -> 0
A7: Collaboration- & Produktivitäts-Tools | B7: =SUMIFS(Positionen!$K$3:$K$74,Positionen!$E$3:$E$74,$A7) -> 277100 | C7: =SUMIFS(Positionen!$L$3:$L$74,Positionen!$E$3:$E$74,$A7) -> 347300 | D7: =C7-B7 -> 70200 | E7: =IF(B7=0,"",D7/B7) -> 0.25333815 | F7: =IF($C$16=0,"",C7/$C$16) -> 0.018895441 | G7: =COUNTIFS(Positionen!$E$3:$E$74,$A7) -> 9 | H7: =COUNTIFS(Positionen!$E$3:$E$74,$A7,Positionen!$O$3:$O$74,"neu") -> 3 | I7: =COUNTIFS(Positionen!$E$3:$E$74,$A7,Positionen!$O$3:$O$74,"entfallen") -> 0
A8: Digital Signage | B8: =SUMIFS(Positionen!$K$3:$K$74,Positionen!$E$3:$E$74,$A8) -> 8000 | C8: =SUMIFS(Positionen!$L$3:$L$74,Positionen!$E$3:$E$74,$A8) -> 8000 | D8: =C8-B8 -> 0 | E8: =IF(B8=0,"",D8/B8) -> 0 | F8: =IF($C$16=0,"",C8/$C$16) -> 0.00043525346 | G8: =COUNTIFS(Positionen!$E$3:$E$74,$A8) -> 2 | H8: =COUNTIFS(Positionen!$E$3:$E$74,$A8,Positionen!$O$3:$O$74,"neu") -> 0 | I8: =COUNTIFS(Positionen!$E$3:$E$74,$A8,Positionen!$O$3:$O$74,"entfallen") -> 0
A9: E-Mail & Messaging Security | B9: =SUMIFS(Positionen!$K$3:$K$74,Positionen!$E$3:$E$74,$A9) -> 64000 | C9: =SUMIFS(Positionen!$L$3:$L$74,Positionen!$E$3:$E$74,$A9) -> 62000 | D9: =C9-B9 -> -2000 | E9: =IF(B9=0,"",D9/B9) -> -0.03125 | F9: =IF($C$16=0,"",C9/$C$16) -> 0.0033732143 | G9: =COUNTIFS(Positionen!$E$3:$E$74,$A9) -> 4 | H9: =COUNTIFS(Positionen!$E$3:$E$74,$A9,Positionen!$O$3:$O$74,"neu") -> 1 | I9: =COUNTIFS(Positionen!$E$3:$E$74,$A9,Positionen!$O$3:$O$74,"entfallen") -> 0
A10: ITSM & ServiceNow | B10: =SUMIFS(Positionen!$K$3:$K$74,Positionen!$E$3:$E$74,$A10) -> 1055000 | C10: =SUMIFS(Positionen!$L$3:$L$74,Positionen!$E$3:$E$74,$A10) -> 2810000 | D10: =C10-B10 -> 1755000 | E10: =IF(B10=0,"",D10/B10) -> 1.6635071 | F10: =IF($C$16=0,"",C10/$C$16) -> 0.15288278 | G10: =COUNTIFS(Positionen!$E$3:$E$74,$A10) -> 10 | H10: =COUNTIFS(Positionen!$E$3:$E$74,$A10,Positionen!$O$3:$O$74,"neu") -> 5 | I10: =COUNTIFS(Positionen!$E$3:$E$74,$A10,Positionen!$O$3:$O$74,"entfallen") -> 3
A11: KI & Copilot | B11: =SUMIFS(Positionen!$K$3:$K$74,Positionen!$E$3:$E$74,$A11) -> 465000 | C11: =SUMIFS(Positionen!$L$3:$L$74,Positionen!$E$3:$E$74,$A11) -> 240000 | D11: =C11-B11 -> -225000 | E11: =IF(B11=0,"",D11/B11) -> -0.48387097 | F11: =IF($C$16=0,"",C11/$C$16) -> 0.013057604 | G11: =COUNTIFS(Positionen!$E$3:$E$74,$A11) -> 2 | H11: =COUNTIFS(Positionen!$E$3:$E$74,$A11,Positionen!$O$3:$O$74,"neu") -> 0 | I11: =COUNTIFS(Positionen!$E$3:$E$74,$A11,Positionen!$O$3:$O$74,"entfallen") -> 0
A12: Microsoft M365 Lizenzen | B12: =SUMIFS(Positionen!$K$3:$K$74,Positionen!$E$3:$E$74,$A12) -> 7925500 | C12: =SUMIFS(Positionen!$L$3:$L$74,Positionen!$E$3:$E$74,$A12) -> 7800000 | D12: =C12-B12 -> -125500 | E12: =IF(B12=0,"",D12/B12) -> -0.015834963 | F12: =IF($C$16=0,"",C12/$C$16) -> 0.42437213 | G12: =COUNTIFS(Positionen!$E$3:$E$74,$A12) -> 10 | H12: =COUNTIFS(Positionen!$E$3:$E$74,$A12,Positionen!$O$3:$O$74,"neu") -> 0 | I12: =COUNTIFS(Positionen!$E$3:$E$74,$A12,Positionen!$O$3:$O$74,"entfallen") -> 0
A13: Output Management & Druck | B13: =SUMIFS(Positionen!$K$3:$K$74,Positionen!$E$3:$E$74,$A13) -> 131000 | C13: =SUMIFS(Positionen!$L$3:$L$74,Positionen!$E$3:$E$74,$A13) -> 154600 | D13: =C13-B13 -> 23600 | E13: =IF(B13=0,"",D13/B13) -> 0.18015267 | F13: =IF($C$16=0,"",C13/$C$16) -> 0.0084112732 | G13: =COUNTIFS(Positionen!$E$3:$E$74,$A13) -> 6 | H13: =COUNTIFS(Positionen!$E$3:$E$74,$A13,Positionen!$O$3:$O$74,"neu") -> 1 | I13: =COUNTIFS(Positionen!$E$3:$E$74,$A13,Positionen!$O$3:$O$74,"entfallen") -> 1
A14: Service Desk & User Support | B14: =SUMIFS(Positionen!$K$3:$K$74,Positionen!$E$3:$E$74,$A14) -> 466200 | C14: =SUMIFS(Positionen!$L$3:$L$74,Positionen!$E$3:$E$74,$A14) -> 458400 | D14: =C14-B14 -> -7800 | E14: =IF(B14=0,"",D14/B14) -> -0.016731017 | F14: =IF($C$16=0,"",C14/$C$16) -> 0.024940023 | G14: =COUNTIFS(Positionen!$E$3:$E$74,$A14) -> 3 | H14: =COUNTIFS(Positionen!$E$3:$E$74,$A14,Positionen!$O$3:$O$74,"neu") -> 0 | I14: =COUNTIFS(Positionen!$E$3:$E$74,$A14,Positionen!$O$3:$O$74,"entfallen") -> 0
A15: Unified Communications & Telefonie | B15: =SUMIFS(Positionen!$K$3:$K$74,Positionen!$E$3:$E$74,$A15) -> 1819500 | C15: =SUMIFS(Positionen!$L$3:$L$74,Positionen!$E$3:$E$74,$A15) -> 2394295 | D15: =C15-B15 -> 574795 | E15: =IF(B15=0,"",D15/B15) -> 0.31590822 | F15: =IF($C$16=0,"",C15/$C$16) -> 0.13026565 | G15: =COUNTIFS(Positionen!$E$3:$E$74,$A15) -> 18 | H15: =COUNTIFS(Positionen!$E$3:$E$74,$A15,Positionen!$O$3:$O$74,"neu") -> 3 | I15: =COUNTIFS(Positionen!$E$3:$E$74,$A15,Positionen!$O$3:$O$74,"entfallen") -> 1
A16: Gesamt | B16: =SUM(B6:B15) -> 16164300 | C16: =SUM(C6:C15) -> 18380095 | D16: =SUM(D6:D15) -> 2215795 | E16: =IF(B16=0,"",D16/B16) -> 0.13707955 | F16: =IF(C16=0,"",C16/C16) -> 1 | G16: =SUM(G6:G15) -> 72 | H16: =SUM(H6:H15) -> 13 | I16: =SUM(I6:I15) -> 5
A19: B) Budget FY27 je Thema und Cost Center (bereinigte Sicht)
A20: Thema | B20: DE2060204 | C20: DE206210 | D20: Gesamt FY27
A21: Client & Endgeräte (L-EDV) | B21: =SUMIFS(Positionen!$L$3:$L$74,Positionen!$E$3:$E$74,$A21,Positionen!$A$3:$A$74,B$20) -> 4083000 | C21: =SUMIFS(Positionen!$L$3:$L$74,Positionen!$E$3:$E$74,$A21,Positionen!$A$3:$A$74,C$20) -> 22500 | D21: =SUM(B21:C21) -> 4105500
A22: Collaboration- & Produktivitäts-Tools | B22: =SUMIFS(Positionen!$L$3:$L$74,Positionen!$E$3:$E$74,$A22,Positionen!$A$3:$A$74,B$20) -> 0 | C22: =SUMIFS(Positionen!$L$3:$L$74,Positionen!$E$3:$E$74,$A22,Positionen!$A$3:$A$74,C$20) -> 347300 | D22: =SUM(B22:C22) -> 347300
A23: Digital Signage | B23: =SUMIFS(Positionen!$L$3:$L$74,Positionen!$E$3:$E$74,$A23,Positionen!$A$3:$A$74,B$20) -> 0 | C23: =SUMIFS(Positionen!$L$3:$L$74,Positionen!$E$3:$E$74,$A23,Positionen!$A$3:$A$74,C$20) -> 8000 | D23: =SUM(B23:C23) -> 8000
A24: E-Mail & Messaging Security | B24: =SUMIFS(Positionen!$L$3:$L$74,Positionen!$E$3:$E$74,$A24,Positionen!$A$3:$A$74,B$20) -> 0 | C24: =SUMIFS(Positionen!$L$3:$L$74,Positionen!$E$3:$E$74,$A24,Positionen!$A$3:$A$74,C$20) -> 62000 | D24: =SUM(B24:C24) -> 62000
A25: ITSM & ServiceNow | B25: =SUMIFS(Positionen!$L$3:$L$74,Positionen!$E$3:$E$74,$A25,Positionen!$A$3:$A$74,B$20) -> 2810000 | C25: =SUMIFS(Positionen!$L$3:$L$74,Positionen!$E$3:$E$74,$A25,Positionen!$A$3:$A$74,C$20) -> 0 | D25: =SUM(B25:C25) -> 2810000
A26: KI & Copilot | B26: =SUMIFS(Positionen!$L$3:$L$74,Positionen!$E$3:$E$74,$A26,Positionen!$A$3:$A$74,B$20) -> 0 | C26: =SUMIFS(Positionen!$L$3:$L$74,Positionen!$E$3:$E$74,$A26,Positionen!$A$3:$A$74,C$20) -> 240000 | D26: =SUM(B26:C26) -> 240000
A27: Microsoft M365 Lizenzen | B27: =SUMIFS(Positionen!$L$3:$L$74,Positionen!$E$3:$E$74,$A27,Positionen!$A$3:$A$74,B$20) -> 0 | C27: =SUMIFS(Positionen!$L$3:$L$74,Positionen!$E$3:$E$74,$A27,Positionen!$A$3:$A$74,C$20) -> 7800000 | D27: =SUM(B27:C27) -> 7800000
A28: Output Management & Druck | B28: =SUMIFS(Positionen!$L$3:$L$74,Positionen!$E$3:$E$74,$A28,Positionen!$A$3:$A$74,B$20) -> 154600 | C28: =SUMIFS(Positionen!$L$3:$L$74,Positionen!$E$3:$E$74,$A28,Positionen!$A$3:$A$74,C$20) -> 0 | D28: =SUM(B28:C28) -> 154600
A29: Service Desk & User Support | B29: =SUMIFS(Positionen!$L$3:$L$74,Positionen!$E$3:$E$74,$A29,Positionen!$A$3:$A$74,B$20) -> 458400 | C29: =SUMIFS(Positionen!$L$3:$L$74,Positionen!$E$3:$E$74,$A29,Positionen!$A$3:$A$74,C$20) -> 0 | D29: =SUM(B29:C29) -> 458400
A30: Unified Communications & Telefonie | B30: =SUMIFS(Positionen!$L$3:$L$74,Positionen!$E$3:$E$74,$A30,Positionen!$A$3:$A$74,B$20) -> 70000 | C30: =SUMIFS(Positionen!$L$3:$L$74,Positionen!$E$3:$E$74,$A30,Positionen!$A$3:$A$74,C$20) -> 2324295 | D30: =SUM(B30:C30) -> 2394295
A31: Gesamt | B31: =SUM(B21:B30) -> 7576000 | C31: =SUM(C21:C30) -> 10804095 | D31: =SUM(D21:D30) -> 18380095
A34: C) Veränderung FY26 → FY27 je Thema und Cost Center (bereinigte Sicht)
A35: Thema | B35: DE2060204 | C35: DE206210 | D35: Delta gesamt
A36: Client & Endgeräte (L-EDV) | B36: =SUMIFS(Positionen!$L$3:$L$74,Positionen!$E$3:$E$74,$A36,Positionen!$A$3:$A$74,B$35)-SUMIFS(Positionen!$K$3:$K$74,Positionen!$E$3:$E$74,$A36,Positionen!$A$3:$A$74,B$35) -> 145000 | C36: =SUMIFS(Positionen!$L$3:$L$74,Positionen!$E$3:$E$74,$A36,Positionen!$A$3:$A$74,C$35)-SUMIFS(Positionen!$K$3:$K$74,Positionen!$E$3:$E$74,$A36,Positionen!$A$3:$A$74,C$35) -> 7500 | D36: =SUM(B36:C36) -> 152500
A37: Collaboration- & Produktivitäts-Tools | B37: =SUMIFS(Positionen!$L$3:$L$74,Positionen!$E$3:$E$74,$A37,Positionen!$A$3:$A$74,B$35)-SUMIFS(Positionen!$K$3:$K$74,Positionen!$E$3:$E$74,$A37,Positionen!$A$3:$A$74,B$35) -> 0 | C37: =SUMIFS(Positionen!$L$3:$L$74,Positionen!$E$3:$E$74,$A37,Positionen!$A$3:$A$74,C$35)-SUMIFS(Positionen!$K$3:$K$74,Positionen!$E$3:$E$74,$A37,Positionen!$A$3:$A$74,C$35) -> 70200 | D37: =SUM(B37:C37) -> 70200
A38: Digital Signage | B38: =SUMIFS(Positionen!$L$3:$L$74,Positionen!$E$3:$E$74,$A38,Positionen!$A$3:$A$74,B$35)-SUMIFS(Positionen!$K$3:$K$74,Positionen!$E$3:$E$74,$A38,Positionen!$A$3:$A$74,B$35) -> 0 | C38: =SUMIFS(Positionen!$L$3:$L$74,Positionen!$E$3:$E$74,$A38,Positionen!$A$3:$A$74,C$35)-SUMIFS(Positionen!$K$3:$K$74,Positionen!$E$3:$E$74,$A38,Positionen!$A$3:$A$74,C$35) -> 0 | D38: =SUM(B38:C38) -> 0
A39: E-Mail & Messaging Security | B39: =SUMIFS(Positionen!$L$3:$L$74,Positionen!$E$3:$E$74,$A39,Positionen!$A$3:$A$74,B$35)-SUMIFS(Positionen!$K$3:$K$74,Positionen!$E$3:$E$74,$A39,Positionen!$A$3:$A$74,B$35) -> 0 | C39: =SUMIFS(Positionen!$L$3:$L$74,Positionen!$E$3:$E$74,$A39,Positionen!$A$3:$A$74,C$35)-SUMIFS(Positionen!$K$3:$K$74,Positionen!$E$3:$E$74,$A39,Positionen!$A$3:$A$74,C$35) -> -2000 | D39: =SUM(B39:C39) -> -2000
A40: ITSM & ServiceNow | B40: =SUMIFS(Positionen!$L$3:$L$74,Positionen!$E$3:$E$74,$A40,Positionen!$A$3:$A$74,B$35)-SUMIFS(Positionen!$K$3:$K$74,Positionen!$E$3:$E$74,$A40,Positionen!$A$3:$A$74,B$35) -> 1755000 | C40: =SUMIFS(Positionen!$L$3:$L$74,Positionen!$E$3:$E$74,$A40,Positionen!$A$3:$A$74,C$35)-SUMIFS(Positionen!$K$3:$K$74,Positionen!$E$3:$E$74,$A40,Positionen!$A$3:$A$74,C$35) -> 0 | D40: =SUM(B40:C40) -> 1755000
A41: KI & Copilot | B41: =SUMIFS(Positionen!$L$3:$L$74,Positionen!$E$3:$E$74,$A41,Positionen!$A$3:$A$74,B$35)-SUMIFS(Positionen!$K$3:$K$74,Positionen!$E$3:$E$74,$A41,Positionen!$A$3:$A$74,B$35) -> 0 | C41: =SUMIFS(Positionen!$L$3:$L$74,Positionen!$E$3:$E$74,$A41,Positionen!$A$3:$A$74,C$35)-SUMIFS(Positionen!$K$3:$K$74,Positionen!$E$3:$E$74,$A41,Positionen!$A$3:$A$74,C$35) -> -225000 | D41: =SUM(B41:C41) -> -225000
A42: Microsoft M365 Lizenzen | B42: =SUMIFS(Positionen!$L$3:$L$74,Positionen!$E$3:$E$74,$A42,Positionen!$A$3:$A$74,B$35)-SUMIFS(Positionen!$K$3:$K$74,Positionen!$E$3:$E$74,$A42,Positionen!$A$3:$A$74,B$35) -> 0 | C42: =SUMIFS(Positionen!$L$3:$L$74,Positionen!$E$3:$E$74,$A42,Positionen!$A$3:$A$74,C$35)-SUMIFS(Positionen!$K$3:$K$74,Positionen!$E$3:$E$74,$A42,Positionen!$A$3:$A$74,C$35) -> -125500 | D42: =SUM(B42:C42) -> -125500
A43: Output Management & Druck | B43: =SUMIFS(Positionen!$L$3:$L$74,Positionen!$E$3:$E$74,$A43,Positionen!$A$3:$A$74,B$35)-SUMIFS(Positionen!$K$3:$K$74,Positionen!$E$3:$E$74,$A43,Positionen!$A$3:$A$74,B$35) -> 23600 | C43: =SUMIFS(Positionen!$L$3:$L$74,Positionen!$E$3:$E$74,$A43,Positionen!$A$3:$A$74,C$35)-SUMIFS(Positionen!$K$3:$K$74,Positionen!$E$3:$E$74,$A43,Positionen!$A$3:$A$74,C$35) -> 0 | D43: =SUM(B43:C43) -> 23600
A44: Service Desk & User Support | B44: =SUMIFS(Positionen!$L$3:$L$74,Positionen!$E$3:$E$74,$A44,Positionen!$A$3:$A$74,B$35)-SUMIFS(Positionen!$K$3:$K$74,Positionen!$E$3:$E$74,$A44,Positionen!$A$3:$A$74,B$35) -> -7800 | C44: =SUMIFS(Positionen!$L$3:$L$74,Positionen!$E$3:$E$74,$A44,Positionen!$A$3:$A$74,C$35)-SUMIFS(Positionen!$K$3:$K$74,Positionen!$E$3:$E$74,$A44,Positionen!$A$3:$A$74,C$35) -> 0 | D44: =SUM(B44:C44) -> -7800
...

Sheet Positionen
A1: Positionen FY26 / FY27 – sortiert nach Cost Center Code | F1: Hinweis: Cost Center DE2060502 (IPS Management Office NCE) ist auf Anforderung vollständig aus dieser Auswertung ausgeschlossen – mit beiden Jahreswerten.
A2: Cost Center (Sicht) | B2: Cost Center Bezeichnung (FY27) | C2: CC FY26 | D2: CC FY27 | E2: Thema | F2: Position | G2: Kostenart (Konto) | H2: Konto-Nr. | I2: R-Code FY26 | J2: R-Code FY27 | K2: Budget FY26 (EUR) | L2: Budget FY27 (EUR) | M2: Delta (EUR) | N2: Delta % | O2: Status | P2: Bemerkung
A3: DE2060204 | B3: DE2060204 - Support & Operations NCE | C3: DE2060204 | D3: DE2060204 | E3: Client & Endgeräte (L-EDV) | F3: L-EDV Client | G3: Exp. repairs and maint.-IT hardware | H3: 72830300 | I3: R0001976 | J3: R0009540 | K3: 2900000 | L3: 3000000 | M3: =L3-K3 -> 100000 | N3: =IF(K3=0,"",M3/K3) -> 0.034482759 | O3: =IF(K3=0,"neu",IF(L3=0,"entfallen",IF(M3>0,"erhöht",IF(M3<0,"reduziert","unverändert")))) -> erhöht | P3: =IF(C3="","erstmals in FY27",IF(D3="","nur in FY26",IF(C3=D3,"",IF(D3=IFERROR(INDEX('Cost Center'!$C$7:$C$9,MATCH(C3,'Cost Center'!$A$7:$A$9,0)),""),"Reorg-Überführung "&C3&" -> "&D3,"abweichende Verlagerung "&C3&" -> "&D3))))
A4: DE2060204 | B4: DE2060204 - Support & Operations NCE | C4: DE2060204 | D4: DE2060204 | E4: Client & Endgeräte (L-EDV) | F4: L-EDV Drucker Ersatzteile | G4: Expenses for low value assets (for DE 250 EUR - 1000 EUR) | H4: 75500405 | I4: R0001991 | J4: R0009553 | K4: 28000 | L4: 30000 | M4: =L4-K4 -> 2000 | N4: =IF(K4=0,"",M4/K4) -> 0.071428571 | O4: =IF(K4=0,"neu",IF(L4=0,"entfallen",IF(M4>0,"erhöht",IF(M4<0,"reduziert","unverändert")))) -> erhöht | P4: =IF(C4="","erstmals in FY27",IF(D4="","nur in FY26",IF(C4=D4,"",IF(D4=IFERROR(INDEX('Cost Center'!$C$7:$C$9,MATCH(C4,'Cost Center'!$A$7:$A$9,0)),""),"Reorg-Überführung "&C4&" -> "&D4,"abweichende Verlagerung "&C4&" -> "&D4))))
A5: DE2060204 | B5: DE2060204 - Support & Operations NCE | C5: DE2060204 | D5: DE2060204 | E5: Client & Endgeräte (L-EDV) | F5: L-EDV Kleinteile | G5: Expenses for low value assets (for DE 250 EUR - 1000 EUR) | H5: 75500405 | I5: R0001990 | J5: R0009552 | K5: 17000 | L5: 18000 | M5: =L5-K5 -> 1000 | N5: =IF(K5=0,"",M5/K5) -> 0.058823529 | O5: =IF(K5=0,"neu",IF(L5=0,"entfallen",IF(M5>0,"erhöht",IF(M5<0,"reduziert","unverändert")))) -> erhöht | P5: =IF(C5="","erstmals in FY27",IF(D5="","nur in FY26",IF(C5=D5,"",IF(D5=IFERROR(INDEX('Cost Center'!$C$7:$C$9,MATCH(C5,'Cost Center'!$A$7:$A$9,0)),""),"Reorg-Überführung "&C5&" -> "&D5,"abweichende Verlagerung "&C5&" -> "&D5))))
A6: DE2060204 | B6: DE2060204 - Support & Operations NCE | C6: DE2060204 | D6: DE2060204 | E6: Client & Endgeräte (L-EDV) | F6: L-EDV Logistik | G6: Exp. repairs and maint.-IT hardware | H6: 72830300 | I6: R0001978 | J6: R0009542 | K6: 600000 | L6: 620000 | M6: =L6-K6 -> 20000 | N6: =IF(K6=0,"",M6/K6) -> 0.033333333 | O6: =IF(K6=0,"neu",IF(L6=0,"entfallen",IF(M6>0,"erhöht",IF(M6<0,"reduziert","unverändert")))) -> erhöht | P6: =IF(C6="","erstmals in FY27",IF(D6="","nur in FY26",IF(C6=D6,"",IF(D6=IFERROR(INDEX('Cost Center'!$C$7:$C$9,MATCH(C6,'Cost Center'!$A$7:$A$9,0)),""),"Reorg-Überführung "&C6&" -> "&D6,"abweichende Verlagerung "&C6&" -> "&D6))))
A7: DE2060204 | B7: DE2060204 - Support & Operations NCE | C7: DE2060204 | D7: DE2060204 | E7: Client & Endgeräte (L-EDV) | F7: L-EDV Server | G7: Exp. repairs and maint.-IT hardware | H7: 72830300 | I7: R0001977 | J7: R0009541 | K7: 93000 | L7: 115000 | M7: =L7-K7 -> 22000 | N7: =IF(K7=0,"",M7/K7) -> 0.23655914 | O7: =IF(K7=0,"neu",IF(L7=0,"entfallen",IF(M7>0,"erhöht",IF(M7<0,"reduziert","unverändert")))) -> erhöht | P7: =IF(C7="","erstmals in FY27",IF(D7="","nur in FY26",IF(C7=D7,"",IF(D7=IFERROR(INDEX('Cost Center'!$C$7:$C$9,MATCH(C7,'Cost Center'!$A$7:$A$9,0)),""),"Reorg-Überführung "&C7&" -> "&D7,"abweichende Verlagerung "&C7&" -> "&D7))))
A8: DE2060204 | B8: DE2060204 - Support & Operations NCE | C8: DE2060204 | D8: DE2060204 | E8: Client & Endgeräte (L-EDV) | F8: Sammler für IT Kleinteile Stammhaus | G8: Transfer Functional Cost | H8: 20608888 | I8: R0004606 | J8: R0010259 | K8: 300000 | L8: 300000 | M8: =L8-K8 -> 0 | N8: =IF(K8=0,"",M8/K8) -> 0 | O8: =IF(K8=0,"neu",IF(L8=0,"entfallen",IF(M8>0,"erhöht",IF(M8<0,"reduziert","unverändert")))) -> unverändert | P8: =IF(C8="","erstmals in FY27",IF(D8="","nur in FY26",IF(C8=D8,"",IF(D8=IFERROR(INDEX('Cost Center'!$C$7:$C$9,MATCH(C8,'Cost Center'!$A$7:$A$9,0)),""),"Reorg-Überführung "&C8&" -> "&D8,"abweichende Verlagerung "&C8&" -> "&D8))))
A9: DE2060204 | B9: DE2060204 - Support & Operations NCE | C9: DE2060202 | E9: ITSM & ServiceNow | F9: ITSM CSI Fokus | G9: Other. outside serv.-IT related services | H9: 73580730 | I9: R0001933 | K9: 50000 | L9: 0 | M9: =L9-K9 -> -50000 | N9: =IF(K9=0,"",M9/K9) -> -1 | O9: =IF(K9=0,"neu",IF(L9=0,"entfallen",IF(M9>0,"erhöht",IF(M9<0,"reduziert","unverändert")))) -> entfallen | P9: =IF(C9="","erstmals in FY27",IF(D9="","nur in FY26",IF(C9=D9,"",IF(D9=IFERROR(INDEX('Cost Center'!$C$7:$C$9,MATCH(C9,'Cost Center'!$A$7:$A$9,0)),""),"Reorg-Überführung "&C9&" -> "&D9,"abweichende Verlagerung "&C9&" -> "&D9)))) -> nur in FY26
A10: DE2060204 | B10: DE2060204 - Support & Operations NCE | C10: DE2060202 | E10: ITSM & ServiceNow | F10: ITSM Development | G10: Other. outside serv. – IT managed services | H10: 73580740 | I10: R0001934 | K10: 85000 | L10: 0 | M10: =L10-K10 -> -85000 | N10: =IF(K10=0,"",M10/K10) -> -1 | O10: =IF(K10=0,"neu",IF(L10=0,"entfallen",IF(M10>0,"erhöht",IF(M10<0,"reduziert","unverändert")))) -> entfallen | P10: =IF(C10="","erstmals in FY27",IF(D10="","nur in FY26",IF(C10=D10,"",IF(D10=IFERROR(INDEX('Cost Center'!$C$7:$C$9,MATCH(C10,'Cost Center'!$A$7:$A$9,0)),""),"Reorg-Überführung "&C10&" -> "&D10,"abweichende Verlagerung "&C10&" -> "&D10)))) -> nur in FY26
A11: DE2060204 | B11: DE2060204 - Support & Operations NCE | C11: DE2060202 | D11: DE2060204 | E11: ITSM & ServiceNow | F11: ServiceNow Enterpise Contract | G11: Expenses for rent - software | H11: 74200320 | I11: R0001931 | J11: R0009501 | K11: 725000 | L11: 1100000 | M11: =L11-K11 -> 375000 | N11: =IF(K11=0,"",M11/K11) -> 0.51724138 | O11: =IF(K11=0,"neu",IF(L11=0,"entfallen",IF(M11>0,"erhöht",IF(M11<0,"reduziert","unverändert")))) -> erhöht | P11: =IF(C11="","erstmals in FY27",IF(D11="","nur in FY26",IF(C11=D11,"",IF(D11=IFERROR(INDEX('Cost Center'!$C$7:$C$9,MATCH(C11,'Cost Center'!$A$7:$A$9,0)),""),"Reorg-Überführung "&C11&" -> "&D11,"abweichende Verlagerung "&C11&" -> "&D11)))) -> Reorg-Überführung DE2060202 -> DE2060204
A12: DE2060204 | B12: DE2060204 - Support & Operations NCE | D12: DE2060204 | E12: ITSM & ServiceNow | F12: ServiceNow Modul IT Operation Monitoring ITOM (D-020936) | G12: Expenses for rent - software | H12: 74200320 | J12: R0010679 | K12: 0 | L12: 400000 | M12: =L12-K12 -> 400000 | N12: =IF(K12=0,"",M12/K12) | O12: =IF(K12=0,"neu",IF(L12=0,"entfallen",IF(M12>0,"erhöht",IF(M12<0,"reduziert","unverändert")))) -> neu | P12: =IF(C12="","erstmals in FY27",IF(D12="","nur in FY26",IF(C12=D12,"",IF(D12=IFERROR(INDEX('Cost Center'!$C$7:$C$9,MATCH(C12,'Cost Center'!$A$7:$A$9,0)),""),"Reorg-Überführung "&C12&" -> "&D12,"abweichende Verlagerung "&C12&" -> "&D12)))) -> erstmals in FY27
A13: DE2060204 | B13: DE2060204 - Support & Operations NCE | C13: DE2060202 | E13: ITSM & ServiceNow | F13: ServiceNow Modul Release Management (SAP) | G13: Expenses for rent - software | H13: 74200320 | I13: R0004187 | K13: 85000 | L13: 0 | M13: =L13-K13 -> -85000 | N13: =IF(K13=0,"",M13/K13) -> -1 | O13: =IF(K13=0,"neu",IF(L13=0,"entfallen",IF(M13>0,"erhöht",IF(M13<0,"reduziert","unverändert")))) -> entfallen | P13: =IF(C13="","erstmals in FY27",IF(D13="","nur in FY26",IF(C13=D13,"",IF(D13=IFERROR(INDEX('Cost Center'!$C$7:$C$9,MATCH(C13,'Cost Center'!$A$7:$A$9,0)),""),"Reorg-Überführung "&C13&" -> "&D13,"abweichende Verlagerung "&C13&" -> "&D13)))) -> nur in FY26
A14: DE2060204 | B14: DE2060204 - Support & Operations NCE | D14: DE2060204 | E14: ITSM & ServiceNow | F14: ServiceNow Plattform Maintenance | G14: Other. outside serv.-IT related services | H14: 73580730 | J14: R0009504 | K14: 0 | L14: 140000 | M14: =L14-K14 -> 140000 | N14: =IF(K14=0,"",M14/K14) | O14: =IF(K14=0,"neu",IF(L14=0,"entfallen",IF(M14>0,"erhöht",IF(M14<0,"reduziert","unverändert")))) -> neu | P14: =IF(C14="","erstmals in FY27",IF(D14="","nur in FY26",IF(C14=D14,"",IF(D14=IFERROR(INDEX('Cost Center'!$C$7:$C$9,MATCH(C14,'Cost Center'!$A$7:$A$9,0)),""),"Reorg-Überführung "&C14&" -> "&D14,"abweichende Verlagerung "&C14&" -> "&D14)))) -> erstmals in FY27
A15: DE2060204 | B15: DE2060204 - Support & Operations NCE | D15: DE2060204 | E15: ITSM & ServiceNow | F15: ServiceNow Plattform Managed Service Operation | G15: Other. outside serv. – IT managed services | H15: 73580740 | J15: R0009723 | K15: 0 | L15: 120000 | M15: =L15-K15 -> 120000 | N15: =IF(K15=0,"",M15/K15) | O15: =IF(K15=0,"neu",IF(L15=0,"entfallen",IF(M15>0,"erhöht",IF(M15<0,"reduziert","unverändert")))) -> neu | P15: =IF(C15="","erstmals in FY27",IF(D15="","nur in FY26",IF(C15=D15,"",IF(D15=IFERROR(INDEX('Cost Center'!$C$7:$C$9,MATCH(C15,'Cost Center'!$A$7:$A$9,0)),""),"Reorg-Überführung "&C15&" -> "&D15,"abweichende Verlagerung "&C15&" -> "&D15)))) -> erstmals in FY27
A16: DE2060204 | B16: DE2060204 - Support & Operations NCE | D16: DE2060204 | E16: ITSM & ServiceNow | F16: ServiceNow SBS Module | G16: Expenses for rent - software | H16: 74200320 | J16: R0010253 | K16: 0 | L16: 50000 | M16: =L16-K16 -> 50000 | N16: =IF(K16=0,"",M16/K16) | O16: =IF(K16=0,"neu",IF(L16=0,"entfallen",IF(M16>0,"erhöht",IF(M16<0,"reduziert","unverändert")))) -> neu | P16: =IF(C16="","erstmals in FY27",IF(D16="","nur in FY26",IF(C16=D16,"",IF(D16=IFERROR(INDEX('Cost Center'!$C$7:$C$9,MATCH(C16,'Cost Center'!$A$7:$A$9,0)),""),"Reorg-Überführung "&C16&" -> "&D16,"abweichende Verlagerung "&C16&" -> "&D16)))) -> erstmals in FY27
A17: DE2060204 | B17: DE2060204 - Support & Operations NCE | D17: DE2060204 | E17: ITSM & ServiceNow | F17: ServiceNow SEPM Projekt Gestehung 2027 (D-020932) | G17: Other. outside serv.-IT related services | H17: 73580730 | J17: R0010680 | K17: 0 | L17: 800000 | M17: =L17-K17 -> 800000 | N17: =IF(K17=0,"",M17/K17) | O17: =IF(K17=0,"neu",IF(L17=0,"entfallen",IF(M17>0,"erhöht",IF(M17<0,"reduziert","unverändert")))) -> neu | P17: =IF(C17="","erstmals in FY27",IF(D17="","nur in FY26",IF(C17=D17,"",IF(D17=IFERROR(INDEX('Cost Center'!$C$7:$C$9,MATCH(C17,'Cost Center'!$A$7:$A$9,0)),""),"Reorg-Überführung "&C17&" -> "&D17,"abweichende Verlagerung "&C17&" -> "&D17)))) -> erstmals in FY27
A18: DE2060204 | B18: DE2060204 - Support & Operations NCE | C18: DE2060202 | D18: DE2060204 | E18: ITSM & ServiceNow | F18: ServiceNow SPM - Strategic Portfolio Management (D-020932) | G18: Expenses for rent - software | H18: 74200320 | I18: R0008435 | J18: R0010387 | K18: 110000 | L18: 200000 | M18: =L18-K18 -> 90000 | N18: =IF(K18=0,"",M18/K18) -> 0.81818182 | O18: =IF(K18=0,"neu",IF(L18=0,"entfallen",IF(M18>0,"erhöht",IF(M18<0,"reduziert","unverändert")))) -> erhöht | P18: =IF(C18="","erstmals in FY27",IF(D18="","nur in FY26",IF(C18=D18,"",IF(D18=IFERROR(INDEX('Cost Center'!$C$7:$C$9,MATCH(C18,'Cost Center'!$A$7:$A$9,0)),""),"Reorg-Überführung "&C18&" -> "&D18,"abweichende Verlagerung "&C18&" -> "&D18)))) -> Reorg-Überführung DE2060202 -> DE2060204
A19: DE2060204 | B19: DE2060204 - Support & Operations NCE | C19: DE2060204 | D19: DE2060204 | E19: Output Management & Druck | F19: Lexmark DFM | G19: Expenses for rent - software | H19: 74200320 | I19: R0001981 | J19: R0009544 | K19: 25000 | L19: 25600 | M19: =L19-K19 -> 600 | N19: =IF(K19=0,"",M19/K19) -> 0.024 | O19: =IF(K19=0,"neu",IF(L19=0,"entfallen",IF(M19>0,"erhöht",IF(M19<0,"reduziert","unverändert")))) -> erhöht | P19: =IF(C19="","erstmals in FY27",IF(D19="","nur in FY26",IF(C19=D19,"",IF(D19=IFERROR(INDEX('Cost Center'!$C$7:$C$9,MATCH(C19,'Cost Center'!$A$7:$A$9,0)),""),"Reorg-Überführung "&C19&" -> "&D19,"abweichende Verlagerung "&C19&" -> "&D19))))
A20: DE2060204 | B20: DE2060204 - Support & Operations NCE | C20: DE2060204 | E20: Output Management & Druck | F20: Lexmark RFID Support | G20: Exp. repairs and maint.-IT hardware | H20: 72830300 | I20: R0001974 | K20: 12000 | L20: 0 | M20: =L20-K20 -> -12000 | N20: =IF(K20=0,"",M20/K20) -> -1 | O20: =IF(K20=0,"neu",IF(L20=0,"entfallen",IF(M20>0,"erhöht",IF(M20<0,"reduziert","unverändert")))) -> entfallen | P20: =IF(C20="","erstmals in FY27",IF(D20="","nur in FY26",IF(C20=D20,"",IF(D20=IFERROR(INDEX('Cost Center'!$C$7:$C$9,MATCH(C20,'Cost Center'!$A$7:$A$9,0)),""),"Reorg-Überführung "&C20&" -> "&D20,"abweichende Verlagerung "&C20&" -> "&D20)))) -> nur in FY26
A21: DE2060204 | B21: DE2060204 - Support & Operations NCE | D21: DE2060204 | E21: Output Management & Druck | F21: LRS - Lizenzen (dopplung SAC 2025) | G21: Expenses for rent - software | H21: 74200320 | J21: R0009545 | K21: 0 | L21: 25000 | M21: =L21-K21 -> 25000 | N21: =IF(K21=0,"",M21/K21) | O21: =IF(K21=0,"neu",IF(L21=0,"entfallen",IF(M21>0,"erhöht",IF(M21<0,"reduziert","unverändert")))) -> neu | P21: =IF(C21="","erstmals in FY27",IF(D21="","nur in FY26",IF(C21=D21,"",IF(D21=IFERROR(INDEX('Cost Center'!$C$7:$C$9,MATCH(C21,'Cost Center'!$A$7:$A$9,0)),""),"Reorg-Überführung "&C21&" -> "&D21,"abweichende Verlagerung "&C21&" -> "&D21)))) -> erstmals in FY27
A22: DE2060204 | B22: DE2060204 - Support & Operations NCE | C22: DE2060204 | D22: DE2060204 | E22: Output Management & Druck | F22: LRS - VPSX Support | G22: Exp. repairs and maint.-software | H22: 72830100 | I22: R0001983 | J22: R0009546 | K22: 35000 | L22: 35000 | M22: =L22-K22 -> 0 | N22: =IF(K22=0,"",M22/K22) -> 0 | O22: =IF(K22=0,"neu",IF(L22=0,"entfallen",IF(M22>0,"erhöht",IF(M22<0,"reduziert","unverändert")))) -> unverändert | P22: =IF(C22="","erstmals in FY27",IF(D22="","nur in FY26",IF(C22=D22,"",IF(D22=IFERROR(INDEX('Cost Center'!$C$7:$C$9,MATCH(C22,'Cost Center'!$A$7:$A$9,0)),""),"Reorg-Überführung "&C22&" -> "&D22,"abweichende Verlagerung "&C22&" -> "&D22))))
A23: DE2060204 | B23: DE2060204 - Support & Operations NCE | C23: DE2060204 | D23: DE2060204 | E23: Output Management & Druck | F23: LRS - Wartung | G23: Exp. repairs and maint.-software | H23: 72830100 | I23: R0001984 | J23: R0009547 | K23: 50000 | L23: 60000 | M23: =L23-K23 -> 10000 | N23: =IF(K23=0,"",M23/K23) -> 0.2 | O23: =IF(K23=0,"neu",IF(L23=0,"entfallen",IF(M23>0,"erhöht",IF(M23<0,"reduziert","unverändert")))) -> erhöht | P23: =IF(C23="","erstmals in FY27",IF(D23="","nur in FY26",IF(C23=D23,"",IF(D23=IFERROR(INDEX('Cost Center'!$C$7:$C$9,MATCH(C23,'Cost Center'!$A$7:$A$9,0)),""),"Reorg-Überführung "&C23&" -> "&D23,"abweichende Verlagerung "&C23&" -> "&D23))))
A24: DE2060204 | B24: DE2060204 - Support & Operations NCE | C24: DE2060204 | D24: DE2060204 | E24: Output Management & Druck | F24: Plot Management Support | G24: Exp. repairs and maint.-IT hardware | H24: 72830300 | I24: R0001975 | J24: R0009539 | K24: 9000 | L24: 9000 | M24: =L24-K24 -> 0 | N24: =IF(K24=0,"",M24/K24) -> 0 | O24: =IF(K24=0,"neu",IF(L24=0,"entfallen",IF(M24>0,"erhöht",IF(M24<0,"reduziert","unverändert")))) -> unverändert | P24: =IF(C24="","erstmals in FY27",IF(D24="","nur in FY26",IF(C24=D24,"",IF(D24=IFERROR(INDEX('Cost Center'!$C$7:$C$9,MATCH(C24,'Cost Center'!$A$7:$A$9,0)),""),"Reorg-Überführung "&C24&" -> "&D24,"abweichende Verlagerung "&C24&" -> "&D24))))
A25: DE2060204 | B25: DE2060204 - Support & Operations NCE | C25: DE2060204 | D25: DE2060204 | E25: Service Desk & User Support | F25: Managed Service Desk | G25: Other. outside serv. – IT managed services | H25: 73580740 | I25: R0001987 | J25: R0009550 | K25: 223200 | L25: 223200 | M25: =L25-K25 -> 0 | N25: =IF(K25=0,"",M25/K25) -> 0 | O25: =IF(K25=0,"neu",IF(L25=0,"entfallen",IF(M25>0,"erhöht",IF(M25<0,"reduziert","unverändert")))) -> unverändert | P25: =IF(C25="","erstmals in FY27",IF(D25="","nur in FY26",IF(C25=D25,"",IF(D25=IFERROR(INDEX('Cost Center'!$C$7:$C$9,MATCH(C25,'Cost Center'!$A$7:$A$9,0)),""),"Reorg-Überführung "&C25&" -> "&D25,"abweichende Verlagerung "&C25&" -> "&D25))))
A26: DE2060204 | B26: DE2060204 - Support & Operations NCE | C26: DE2060204 | D26: DE2060204 | E26: Service Desk & User Support | F26: Off Hour Bechtle Operations | G26: Other. outside serv.-IT related services | H26: 73580730 | I26: R0004133 | J26: R0010225 | K26: 105000 | L26: 93000 | M26: =L26-K26 -> -12000 | N26: =IF(K26=0,"",M26/K26) -> -0.11428571 | O26: =IF(K26=0,"neu",IF(L26=0,"entfallen",IF(M26>0,"erhöht",IF(M26<0,"reduziert","unverändert")))) -> reduziert | P26: =IF(C26="","erstmals in FY27",IF(D26="","nur in FY26",IF(C26=D26,"",IF(D26=IFERROR(INDEX('Cost Center'!$C$7:$C$9,MATCH(C26,'Cost Center'!$A$7:$A$9,0)),""),"Reorg-Überführung "&C26&" -> "&D26,"abweichende Verlagerung "&C26&" -> "&D26))))
A27: DE2060204 | B27: DE2060204 - Support & Operations NCE | C27: DE2060204 | D27: DE2060204 | E27: Service Desk & User Support | F27: On-Hour Bechtle | G27: Other. outside serv.-IT related services | H27: 73580730 | I27: R0004136 | J27: R0010226 | K27: 138000 | L27: 142200 | M27: =L27-K27 -> 4200 | N27: =IF(K27=0,"",M27/K27) -> 0.030434783 | O27: =IF(K27=0,"neu",IF(L27=0,"entfallen",IF(M27>0,"erhöht",IF(M27<0,"reduziert","unverändert")))) -> erhöht | P27: =IF(C27="","erstmals in FY27",IF(D27="","nur in FY26",IF(C27=D27,"",IF(D27=IFERROR(INDEX('Cost Center'!$C$7:$C$9,MATCH(C27,'Cost Center'!$A$7:$A$9,0)),""),"Reorg-Überführung "&C27&" -> "&D27,"abweichende Verlagerung "&C27&" -> "&D27))))
A28: DE2060204 | B28: DE2060204 - Support & Operations NCE | C28: DE2060204 | E28: Unified Communications & Telefonie | F28: Alarming - SMS | G28: Other. outside serv. – IT managed services | H28: 73580740 | I28: R0001985 | K28: 5500 | L28: 0 | M28: =L28-K28 -> -5500 | N28: =IF(K28=0,"",M28/K28) -> -1 | O28: =IF(K28=0,"neu",IF(L28=0,"entfallen",IF(M28>0,"erhöht",IF(M28<0,"reduziert","unverändert")))) -> entfallen | P28: =IF(C28="","erstmals in FY27",IF(D28="","nur in FY26",IF(C28=D28,"",IF(D28=IFERROR(INDEX('Cost Center'!$C$7:$C$9,MATCH(C28,'Cost Center'!$A$7:$A$9,0)),""),"Reorg-Überführung "&C28&" -> "&D28,"abweichende Verlagerung "&C28&" -> "&D28)))) -> nur in FY26
A29: DE2060204 | B29: DE2060204 - Support & Operations NCE | C29: DE2060204 | D29: DE2060204 | E29: Unified Communications & Telefonie | F29: Heydt Kommunikation 2nd Level UC | G29: Other. outside serv. – IT managed services | H29: 73580740 | I29: R0001988 | J29: R0009551 | K29: 50000 | L29: 50000 | M29: =L29-K29 -> 0 | N29: =IF(K29=0,"",M29/K29) -> 0 | O29: =IF(K29=0,"neu",IF(L29=0,"entfallen",IF(M29>0,"erhöht",IF(M29<0,"reduziert","unverändert")))) -> unverändert | P29: =IF(C29="","erstmals in FY27",IF(D29="","nur in FY26",IF(C29=D29,"",IF(D29=IFERROR(INDEX('Cost Center'!$C$7:$C$9,MATCH(C29,'Cost Center'!$A$7:$A$9,0)),""),"Reorg-Überführung "&C29&" -> "&D29,"abweichende Verlagerung "&C29&" -> "&D29))))
A30: DE2060204 | B30: DE2060204 - Support & Operations NCE | C30: DE2060204 | D30: DE2060204 | E30: Unified Communications & Telefonie | F30: L-EDV Instandhaltung UC | G30: Exp. repairs and maint.-IT hardware | H30: 72830300 | I30: R0001979 | J30: R0009543 | K30: 20000 | L30: 20000 | M30: =L30-K30 -> 0 | N30: =IF(K30=0,"",M30/K30) -> 0 | O30: =IF(K30=0,"neu",IF(L30=0,"entfallen",IF(M30>0,"erhöht",IF(M30<0,"reduziert","unverändert")))) -> unverändert | P30: =IF(C30="","erstmals in FY27",IF(D30="","nur in FY26",IF(C30=D30,"",IF(D30=IFERROR(INDEX('Cost Center'!$C$7:$C$9,MATCH(C30,'Cost Center'!$A$7:$A$9,0)),""),"Reorg-Überführung "&C30&" -> "&D30,"abweichende Verlagerung "&C30&" -> "&D30))))
A31: DE206210 | B31: DE206210 - Modern Workplace & Experience | C31: DE2060203 | D31: DE206210 | E31: Client & Endgeräte (L-EDV) | F31: GWG bis 1.000 € | G31: Expenses for low value assets (for DE 250 EUR - 1000 EUR) | H31: 75500405 | I31: R0001972 | J31: R0009536 | K31: 10000 | L31: 17500 | M31: =L31-K31 -> 7500 | N31: =IF(K31=0,"",M31/K31) -> 0.75 | O31: =IF(K31=0,"neu",IF(L31=0,"entfallen",IF(M31>0,"erhöht",IF(M31<0,"reduziert","unverändert")))) -> erhöht | P31: =IF(C31="","erstmals in FY27",IF(D31="","nur in FY26",IF(C31=D31,"",IF(D31=IFERROR(INDEX('Cost Center'!$C$7:$C$9,MATCH(C31,'Cost Center'!$A$7:$A$9,0)),""),"Reorg-Überführung "&C31&" -> "&D31,"abweichende Verlagerung "&C31&" -> "&D31)))) -> Reorg-Überführung DE2060203 -> DE206210
A32: DE206210 | B32: DE206210 - Modern Workplace & Experience | C32: DE2060203 | D32: DE206210 | E32: Client & Endgeräte (L-EDV) | F32: GWG bis 250 € | G32: Expenses for small items < 250 EUR | H32: 75500400 | I32: R0001973 | J32: R0009537 | K32: 5000 | L32: 5000 | M32: =L32-K32 -> 0 | N32: =IF(K32=0,"",M32/K32) -> 0 | O32: =IF(K32=0,"neu",IF(L32=0,"entfallen",IF(M32>0,"erhöht",IF(M32<0,"reduziert","unverändert")))) -> unverändert | P32: =IF(C32="","erstmals in FY27",IF(D32="","nur in FY26",IF(C32=D32,"",IF(D32=IFERROR(INDEX('Cost Center'!$C$7:$C$9,MATCH(C32,'Cost Center'!$A$7:$A$9,0)),""),"Reorg-Überführung "&C32&" -> "&D32,"abweichende Verlagerung "&C32&" -> "&D32)))) -> Reorg-Überführung DE2060203 -> DE206210
A33: DE206210 | B33: DE206210 - Modern Workplace & Experience | C33: DE2060203 | D33: DE206210 | E33: Collaboration- & Produktivitäts-Tools | F33: Boardwise VIP Solution | G33: Expenses for rent - software | H33: 74200320 | I33: R0001955 | J33: R0009520 | K33: 31100 | L33: 31100 | M33: =L33-K33 -> 0 | N33: =IF(K33=0,"",M33/K33) -> 0 | O33: =IF(K33=0,"neu",IF(L33=0,"entfallen",IF(M33>0,"erhöht",IF(M33<0,"reduziert","unverändert")))) -> unverändert | P33: =IF(C33="","erstmals in FY27",IF(D33="","nur in FY26",IF(C33=D33,"",IF(D33=IFERROR(INDEX('Cost Center'!$C$7:$C$9,MATCH(C33,'Cost Center'!$A$7:$A$9,0)),""),"Reorg-Überführung "&C33&" -> "&D33,"abweichende Verlagerung "&C33&" -> "&D33)))) -> Reorg-Überführung DE2060203 -> DE206210
A34: DE206210 | B34: DE206210 - Modern Workplace & Experience | C34: DE2060203 | D34: DE206210 | E34: Collaboration- & Produktivitäts-Tools | F34: Efficient Elements Microsoft PowerPoint Plugin | G34: Expenses for rent - software | H34: 74200320 | I34: R0001953 | J34: R0009518 | K34: 28000 | L34: 26200 | M34: =L34-K34 -> -1800 | N34: =IF(K34=0,"",M34/K34) -> -0.064285714 | O34: =IF(K34=0,"neu",IF(L34=0,"entfallen",IF(M34>0,"erhöht",IF(M34<0,"reduziert","unverändert")))) -> reduziert | P34: =IF(C34="","erstmals in FY27",IF(D34="","nur in FY26",IF(C34=D34,"",IF(D34=IFERROR(INDEX('Cost Center'!$C$7:$C$9,MATCH(C34,'Cost Center'!$A$7:$A$9,0)),""),"Reorg-Überführung "&C34&" -> "&D34,"abweichende Verlagerung "&C34&" -> "&D34)))) -> Reorg-Überführung DE2060203 -> DE206210
A35: DE206210 | B35: DE206210 - Modern Workplace & Experience | C35: DE2060203 | D35: DE206210 | E35: Collaboration- & Produktivitäts-Tools | F35: M365 Beratung (inkl. Implementierung Schnittstellen z.B.: IDM) | G35: Other. outside serv.-IT related services | H35: 73580730 | I35: R0001968 | J35: R0009532 | K35: 75000 | L35: 70000 | M35: =L35-K35 -> -5000 | N35: =IF(K35=0,"",M35/K35) -> -0.066666667 | O35: =IF(K35=0,"neu",IF(L35=0,"entfallen",IF(M35>0,"erhöht",IF(M35<0,"reduziert","unverändert")))) -> reduziert | P35: =IF(C35="","erstmals in FY27",IF(D35="","nur in FY26",IF(C35=D35,"",IF(D35=IFERROR(INDEX('Cost Center'!$C$7:$C$9,MATCH(C35,'Cost Center'!$A$7:$A$9,0)),""),"Reorg-Überführung "&C35&" -> "&D35,"abweichende Verlagerung "&C35&" -> "&D35)))) -> Reorg-Überführung DE2060203 -> DE206210
A36: DE206210 | B36: DE206210 - Modern Workplace & Experience | C36: DE2060203 | D36: DE206210 | E36: Collaboration- & Produktivitäts-Tools | F36: MHS Consulting Support & Entwicklung | G36: Other. outside serv.-IT related services | H36: 73580730 | I36: R0001964 | J36: R0009528 | K36: 20000 | L36: 20000 | M36: =L36-K36 -> 0 | N36: =IF(K36=0,"",M36/K36) -> 0 | O36: =IF(K36=0,"neu",IF(L36=0,"entfallen",IF(M36>0,"erhöht",IF(M36<0,"reduziert","unverändert")))) -> unverändert | P36: =IF(C36="","erstmals in FY27",IF(D36="","nur in FY26",IF(C36=D36,"",IF(D36=IFERROR(INDEX('Cost Center'!$C$7:$C$9,MATCH(C36,'Cost Center'!$A$7:$A$9,0)),""),"Reorg-Überführung "&C36&" -> "&D36,"abweichende Verlagerung "&C36&" -> "&D36)))) -> Reorg-Überführung DE2060203 -> DE206210
A37: DE206210 | B37: DE206210 - Modern Workplace & Experience | C37: DE2060203 | D37: DE206210 | E37: Collaboration- & Produktivitäts-Tools | F37: Mural Whiteboard Solution | G37: Expenses for rent - software | H37: 74200320 | I37: R0001950 | J37: R0009515 | K37: 30000 | L37: 30000 | M37: =L37-K37 -> 0 | N37: =IF(K37=0,"",M37/K37) -> 0 | O37: =IF(K37=0,"neu",IF(L37=0,"entfallen",IF(M37>0,"erhöht",IF(M37<0,"reduziert","unverändert")))) -> unverändert | P37: =IF(C37="","erstmals in FY27",IF(D37="","nur in FY26",IF(C37=D37,"",IF(D37=IFERROR(INDEX('Cost Center'!$C$7:$C$9,MATCH(C37,'Cost Center'!$A$7:$A$9,0)),""),"Reorg-Überführung "&C37&" -> "&D37,"abweichende Verlagerung "&C37&" -> "&D37)))) -> Reorg-Überführung DE2060203 -> DE206210
A38: DE206210 | B38: DE206210 - Modern Workplace & Experience | D38: DE206210 | E38: Collaboration- & Produktivitäts-Tools | F38: Novacapta Wartung & Support | G38: Other. outside serv.-IT related services | H38: 73580730 | J38: R0009529 | K38: 0 | L38: 60000 | M38: =L38-K38 -> 60000 | N38: =IF(K38=0,"",M38/K38) | O38: =IF(K38=0,"neu",IF(L38=0,"entfallen",IF(M38>0,"erhöht",IF(M38<0,"reduziert","unverändert")))) -> neu | P38: =IF(C38="","erstmals in FY27",IF(D38="","nur in FY26",IF(C38=D38,"",IF(D38=IFERROR(INDEX('Cost Center'!$C$7:$C$9,MATCH(C38,'Cost Center'!$A$7:$A$9,0)),""),"Reorg-Überführung "&C38&" -> "&D38,"abweichende Verlagerung "&C38&" -> "&D38)))) -> erstmals in FY27
A39: DE206210 | B39: DE206210 - Modern Workplace & Experience | D39: DE206210 | E39: Collaboration- & Produktivitäts-Tools | F39: ShareGate Migrations-Tool | G39: Expenses for rent - software | H39: 74200320 | J39: R0009514 | K39: 0 | L39: 20000 | M39: =L39-K39 -> 20000 | N39: =IF(K39=0,"",M39/K39) | O39: =IF(K39=0,"neu",IF(L39=0,"entfallen",IF(M39>0,"erhöht",IF(M39<0,"reduziert","unverändert")))) -> neu | P39: =IF(C39="","erstmals in FY27",IF(D39="","nur in FY26",IF(C39=D39,"",IF(D39=IFERROR(INDEX('Cost Center'!$C$7:$C$9,MATCH(C39,'Cost Center'!$A$7:$A$9,0)),""),"Reorg-Überführung "&C39&" -> "&D39,"abweichende Verlagerung "&C39&" -> "&D39)))) -> erstmals in FY27
A40: DE206210 | B40: DE206210 - Modern Workplace & Experience | C40: DE2060203 | D40: DE206210 | E40: Collaboration- & Produktivitäts-Tools | F40: Think-Cell Microsoft PowerPoint Plugin | G40: Expenses for rent - software | H40: 74200320 | I40: R0001954 | J40: R0009519 | K40: 93000 | L40: 88500 | M40: =L40-K40 -> -4500 | N40: =IF(K40=0,"",M40/K40) -> -0.048387097 | O40: =IF(K40=0,"neu",IF(L40=0,"entfallen",IF(M40>0,"erhöht",IF(M40<0,"reduziert","unverändert")))) -> reduziert | P40: =IF(C40="","erstmals in FY27",IF(D40="","nur in FY26",IF(C40=D40,"",IF(D40=IFERROR(INDEX('Cost Center'!$C$7:$C$9,MATCH(C40,'Cost Center'!$A$7:$A$9,0)),""),"Reorg-Überführung "&C40&" -> "&D40,"abweichende Verlagerung "&C40&" -> "&D40)))) -> Reorg-Überführung DE2060203 -> DE206210
...

Sheet Rohdaten sfinx
A1: Resource Coin | G1: FY26 | H1: FY27
A2: Cost center code | B2: Cost center | C2: Name | D2: Original Currency | E2: Account number | F2: Account name | G2: Total FY26 | H2: Total FY27
A3: 2026 - DE2060202 | B3: 2026 - DE2060202 - ITSM+ServiceNow NCE | C3: R0004187 - ServiceNow Modul Release Management (SAP) | D3: EUR | E3: 74200320 | F3: Expenses for rent - software | G3: 85000
A4: 2026 - DE2060202 | B4: 2026 - DE2060202 - ITSM+ServiceNow NCE | C4: R0001931 - ServiceNow Enterpise Contract | D4: EUR | E4: 74200320 | F4: Expenses for rent - software | G4: 725000
A5: 2026 - DE2060202 | B5: 2026 - DE2060202 - ITSM+ServiceNow NCE | C5: R0008435 - ServiceNow SPM - Strategic Portfolio Management | D5: EUR | E5: 74200320 | F5: Expenses for rent - software | G5: 110000
A6: 2026 - DE2060202 | B6: 2026 - DE2060202 - ITSM+ServiceNow NCE | C6: R0001935 - SMO Operations | D6: EUR | E6: 73580740 | F6: Other. outside serv. – IT managed services | G6: 300000
A7: 2026 - DE2060202 | B7: 2026 - DE2060202 - ITSM+ServiceNow NCE | C7: R0001933 - ITSM CSI Fokus | D7: EUR | E7: 73580730 | F7: Other. outside serv.-IT related services | G7: 50000
A8: 2026 - DE2060202 | B8: 2026 - DE2060202 - ITSM+ServiceNow NCE | C8: R0001934 - ITSM Development | D8: EUR | E8: 73580740 | F8: Other. outside serv. – IT managed services | G8: 85000
A9: 2026 - DE2060203 | B9: 2026 - DE2060203 - Digital Collabo. NCE | C9: R0001966 - avodaq Beratung | D9: EUR | E9: 73580730 | F9: Other. outside serv.-IT related services | G9: 50000
A10: 2026 - DE2060203 | B10: 2026 - DE2060203 - Digital Collabo. NCE | C10: R0009064 - M365 Copilot und Copilot Studio | D10: EUR | E10: 74200320 | F10: Expenses for rent - software | G10: 450000
A11: 2026 - DE2060203 | B11: 2026 - DE2060203 - Digital Collabo. NCE | C11: R0001951 - Microsoft M365 EA - Visio Plan 1 | D11: EUR | E11: 74200320 | F11: Expenses for rent - software | G11: 22000
A12: 2026 - DE2060203 | B12: 2026 - DE2060203 - Digital Collabo. NCE | C12: R0001961 - Digital Signage Software | D12: EUR | E12: 72830100 | F12: Exp. repairs and maint.-software | G12: 3000
A13: 2026 - DE2060203 | B13: 2026 - DE2060203 - Digital Collabo. NCE | C13: R0004610 - Managed Service Phone + Meeting (avodaq) | D13: EUR | E13: 73580740 | F13: Other. outside serv. – IT managed services | G13: 680000
A14: 2026 - DE2060203 | B14: 2026 - DE2060203 - Digital Collabo. NCE | C14: R0004613 - Microsoft M365 EA - PowerBI Premium Cap | D14: EUR | E14: 74200320 | F14: Expenses for rent - software | G14: 157000
... A62: 2026 - DE2060204 | B62: 2026 - DE2060204 - Serv. Desk+Sup.NCE | C62: R0001981 - Lexmark DFM | D62: EUR | E62: 74200320 | F62: Expenses for rent - software | G62: 25000
A63: DE2060203 | B63: DE2060203 - Modern Workplace & Experience | C63: R0009524 - Fax over IP | D63: EUR | E63: 72830100 | F63: Exp. repairs and maint.-software | H63: 8500
A64: DE2060203 | B64: DE2060203 - Modern Workplace & Experience | C64: R0010263 - Microsoft M365 EA - PowerBI Premium Cap | D64: EUR | E64: 74200320 | F64: Expenses for rent - software | H64: 157000
A65: DE2060203 | B65: DE2060203 - Modern Workplace & Experience | C65: R0009527 - Heydt Consulting UC Wartung & Support | D65: EUR | E65: 73580730 | F65: Other. outside serv.-IT related services | H65: 45000
A66: DE2060203 | B66: DE2060203 - Modern Workplace & Experience | C66: R0009519 - Think-Cell Microsoft PowerPoint Plugin | D66: EUR | E66: 74200320 | F66: Expenses for rent - software | H66: 88500
A67: DE2060203 | B67: DE2060203 - Modern Workplace & Experience | C67: R0009516 - Microsoft M365 EA - Visio Plan 1 | D67: EUR | E67: 74200320 | F67: Expenses for rent - software | H67: 21000
A68: DE2060203 | B68: DE2060203 - Modern Workplace & Experience | C68: R0009511 - Webex CTI CRM Integration | D68: EUR | E68: 74200320 | F68: Expenses for rent - software | H68: 84250
A69: DE2060203 | B69: DE2060203 - Modern Workplace & Experience | C69: R0009508 - Microsoft M365 EA - SharePoint Storage | D69: EUR | E69: 74200320 | F69: Expenses for rent - software | H69: 90000
A70: DE2060203 | B70: DE2060203 - Modern Workplace & Experience | C70: R0009534 - Fax Managed Service | D70: EUR | E70: 73580740 | F70: Other. outside serv. – IT managed services | H70: 22500
A71: DE2060203 | B71: DE2060203 - Modern Workplace & Experience | C71: R0009515 - Mural Whiteboard Solution | D71: EUR | E71: 74200320 | F71: Expenses for rent - software | H71: 30000
A72: DE2060203 | B72: DE2060203 - Modern Workplace & Experience | C72: R0009509 - Webex FlexPlan - Suite | D72: EUR | E72: 74200320 | F72: Expenses for rent - software | H72: 75000
A73: DE2060203 | B73: DE2060203 - Modern Workplace & Experience | C73: R0009512 - Microsoft M365 EA - Teams Rooms | D73: EUR | E73: 74200320 | F73: Expenses for rent - software | H73: 79000
A74: DE2060203 | B74: DE2060203 - Modern Workplace & Experience | C74: R0009532 - M365 Beratung (inkl. Implementierung Schnittstellen z.B.: IDM) | D74: EUR | E74: 73580730 | F74: Other. outside serv.-IT related services | H74: 70000
... A137: DE2060502 | B137: DE2060502 - IPS Management Office NCE | C137: R0009505 - ITSM: SMO Operations | D137: EUR | E137: 73580740 | F137: Other. outside serv. – IT managed services | H137: 300000
A139: Unveränderter Originalexport. Enthält auch den aus der Auswertung ausgeschlossenen Cost Center DE2060502 – die Summen dieses Blatts weichen deshalb von den Auswertungsblättern ab (siehe Blatt "Legende", Abschnitt 5).

Sheet Legende
A1: Legende, Aufbau und Annahmen
A4: 1) Quelle
A5: Datei | B5: SfinxExport_25082026.xlsx, Blatt "sfinx" (unverändert übernommen in Blatt "Rohdaten sfinx")
A6: Umfang | B6: 60 Positionen FY26 und 75 Positionen FY27, Währung EUR, zusammengeführt zu 72 Vergleichszeilen im Blatt "Positionen"
A7: Quellwerte | B7: Nur die Spalten "Budget FY26" und "Budget FY27" im Blatt "Positionen" sind Werte aus dem Export. Alle anderen Zellen der Mappe sind Formeln und rechnen automatisch neu.
A9: 2) Blattaufbau
A10: Dashboard | B10: Interaktive Sicht mit zwei Dropdowns (Cost Center / Thema), Kennzahlen, vier Diagrammen und der Top-Liste der Veränderungen.
A11: Cost Center | B11: A) organisatorische Überführung FY26 → FY27, B) Ist-Sicht wie gebucht, C) organisatorisch bereinigte Sicht – B und C jeweils mit Diagramm.
A12: Themen | B12: Entwicklung je Thema, Matrix Thema x Cost Center (FY27 und Veränderung) sowie vier Diagramme.
A13: Positionen | B13: Detailtabelle aller Positionen, sortiert nach Cost-Center-Code, Thema und Bezeichnung. Mit Autofilter.
A14: Berechnung | B14: Hilfsblatt: Auswahllisten und formelbasierte Diagrammquellen des Dashboards. Bitte nicht löschen.
A15: Rohdaten sfinx | B15: Originalexport zur Nachvollziehbarkeit.
A17: 3) Zuordnung der Positionen über die Jahre
A18: Matching | B18: FY26- und FY27-Positionen werden über die bereinigte Bezeichnung verknüpft (ohne R-Nummer, ohne Demand-Nummer "(D-0xxxxx)", ohne Präfix "ITSM:"). Die R-Nummern beider Jahre bleiben in den Spalten I und J sichtbar.
A19: Status | B19: "neu" = nur FY27 vorhanden · "entfallen" = nur FY26 vorhanden · "erhöht"/"reduziert"/"unverändert" = in beiden Jahren vorhanden.
A20: Bemerkung | B20: Weist auf einen Cost-Center-Wechsel einer Position zwischen FY26 und FY27 hin (Verlagerung).
A22: 4) Annahmen (bitte prüfen)
A23: Überführung (Vorgabe) | B23: Vom Fachbereich vorgegeben und in Block A des Blatts "Cost Center" dokumentiert: DE2060202 (ITSM+ServiceNow) wurde in DE2060204 integriert · DE2060203 (Digital Collaboration) wurde nach DE206210 (Modern Workplace & Experience) überführt · DE2060204 wird unverändert fortgeführt.
A24: Umschlüsselung DE206210 | B24: Achtung: Der sFinx-Export führt den FY27-Cost-Center von Modern Workplace & Experience noch unter dem alten Code DE2060203. Gemäß Vorgabe werden alle FY27-Zeilen dieses Cost Centers auf den Code DE206210 umgeschlüsselt. Im Blatt "Rohdaten sfinx" steht daher weiterhin DE2060203.
A25: Bereinigte Sicht | B25: Für die vergleichbare Sicht wird eine Position mit beiden Jahreswerten dem FY27-Cost-Center zugeordnet (z. B. ServiceNow Enterprise Contract: FY26 auf DE2060202, FY27 auf DE2060204 – beide Werte werden DE2060204 zugerechnet). Es verbleiben damit die beiden fortgeführten Cost Center DE2060204 und DE206210.
A26: FY26-Positionen ohne Nachfolger | B26: Positionen, die es nur in FY26 gibt, folgen der Überführung aus Block A: ITSM CSI Fokus, ITSM Development und ServiceNow Modul Release Management (SAP) (alle DE2060202) werden in der bereinigten Sicht DE2060204 zugeordnet, Alarming - SMS und Lexmark RFID Support bleiben bei DE2060204.
